# SOME DESCRIPTIVE TITLE.
# Copyright (C) 2001-2025, Python Software Foundation
# This file is distributed under the same license as the Python package.
# FIRST AUTHOR <EMAIL@ADDRESS>, YEAR.
# 
# Translators:
# Rafael Fontenelle <rffontenelle@gmail.com>, 2025
# 
#, fuzzy
msgid ""
msgstr ""
"Project-Id-Version: Python 3.12\n"
"Report-Msgid-Bugs-To: \n"
"POT-Creation-Date: 2025-07-25 16:03+0000\n"
"PO-Revision-Date: 2025-07-18 19:57+0000\n"
"Last-Translator: Rafael Fontenelle <rffontenelle@gmail.com>, 2025\n"
"Language-Team: Chinese (China) (https://app.transifex.com/python-doc/teams/5390/zh_CN/)\n"
"MIME-Version: 1.0\n"
"Content-Type: text/plain; charset=UTF-8\n"
"Content-Transfer-Encoding: 8bit\n"
"Language: zh_CN\n"
"Plural-Forms: nplurals=1; plural=0;\n"

#: ../../library/asyncio-exceptions.rst:8
msgid "Exceptions"
msgstr "异常"

#: ../../library/asyncio-exceptions.rst:10
msgid "**Source code:** :source:`Lib/asyncio/exceptions.py`"
msgstr "**源代码:** :source:`Lib/asyncio/exceptions.py`"

#: ../../library/asyncio-exceptions.rst:16
msgid ""
"A deprecated alias of :exc:`TimeoutError`, raised when the operation has "
"exceeded the given deadline."
msgstr ":exc:`TimeoutError` 的一个已被弃用的别名，会在操作超出了给定的时限时引发。"

#: ../../library/asyncio-exceptions.rst:21
msgid "This class was made an alias of :exc:`TimeoutError`."
msgstr "这个类是 :exc:`TimeoutError` 的别名。"

#: ../../library/asyncio-exceptions.rst:26
msgid "The operation has been cancelled."
msgstr "该操作已被取消。"

#: ../../library/asyncio-exceptions.rst:28
msgid ""
"This exception can be caught to perform custom operations when asyncio Tasks"
" are cancelled.  In almost all situations the exception must be re-raised."
msgstr "取消asyncio任务时，可以捕获此异常以执行自定义操作。在几乎所有情况下，都必须重新引发异常。"

#: ../../library/asyncio-exceptions.rst:34
msgid ""
":exc:`CancelledError` is now a subclass of :class:`BaseException` rather "
"than :class:`Exception`."
msgstr ""
":exc:`CancelledError` 现在是 :class:`BaseException` 的子类而不是 :class:`Exception` "
"的子类。"

#: ../../library/asyncio-exceptions.rst:39
msgid "Invalid internal state of :class:`Task` or :class:`Future`."
msgstr ":class:`Task` 或 :class:`Future` 的内部状态无效。"

#: ../../library/asyncio-exceptions.rst:41
msgid ""
"Can be raised in situations like setting a result value for a *Future* "
"object that already has a result value set."
msgstr "在为已设置结果值的未来对象设置结果值等情况下，可以引发此问题。"

#: ../../library/asyncio-exceptions.rst:47
msgid ""
"The \"sendfile\" syscall is not available for the given socket or file type."
msgstr "\"sendfile\" 系统调用不适用于给定的套接字或文件类型。"

#: ../../library/asyncio-exceptions.rst:50
msgid "A subclass of :exc:`RuntimeError`."
msgstr "子类 :exc:`RuntimeError` 。"

#: ../../library/asyncio-exceptions.rst:55
msgid "The requested read operation did not complete fully."
msgstr "请求的读取操作未完全完成。"

#: ../../library/asyncio-exceptions.rst:57
msgid "Raised by the :ref:`asyncio stream APIs<asyncio-streams>`."
msgstr "由 :ref:`asyncio stream APIs<asyncio-streams>` 提出"

#: ../../library/asyncio-exceptions.rst:59
msgid "This exception is a subclass of :exc:`EOFError`."
msgstr "此异常是 :exc:`EOFError` 的子类。"

#: ../../library/asyncio-exceptions.rst:63
msgid "The total number (:class:`int`) of expected bytes."
msgstr "预期字节的总数（ :class:`int` ）。"

#: ../../library/asyncio-exceptions.rst:67
msgid "A string of :class:`bytes` read before the end of stream was reached."
msgstr "到达流结束之前读取的 :class:`bytes` 字符串。"

#: ../../library/asyncio-exceptions.rst:72
msgid "Reached the buffer size limit while looking for a separator."
msgstr "在查找分隔符时达到缓冲区大小限制。"

#: ../../library/asyncio-exceptions.rst:74
msgid "Raised by the :ref:`asyncio stream APIs <asyncio-streams>`."
msgstr "由 :ref:`asyncio stream APIs <asyncio-streams>` 提出"

#: ../../library/asyncio-exceptions.rst:78
msgid "The total number of to be consumed bytes."
msgstr "要消耗的字节总数。"
